<mujoco model="Crank_slider_system_V3_Pjoint_Posmod">
  <compiler angle="radian"/>

  <asset>
    <mesh name="base_link" content_type="model/stl" file="base_link.stl" scale="0.001 0.001 0.001"/>
    <mesh name="braket1_1" content_type="model/stl" file="braket1_1.stl" scale="0.001 0.001 0.001"/>
    <mesh name="braket2_1" content_type="model/stl" file="braket2_1.stl" scale="0.001 0.001 0.001"/>
    <mesh name="motor_1" content_type="model/stl" file="motor_1.stl" scale="0.001 0.001 0.001"/>
    <mesh name="motor_shaft_1" content_type="model/stl" file="motor_shaft_1.stl" scale="0.001 0.001 0.001"/>
    <mesh name="Link1_1" content_type="model/stl" file="Link1_1.stl" scale="0.001 0.001 0.001"/>
    <mesh name="Link2_1" content_type="model/stl" file="Link2_1.stl" scale="0.001 0.001 0.001"/>
    <mesh name="Link3_1" content_type="model/stl" file="Link3_1.stl" scale="0.001 0.001 0.001"/>
    <mesh name="Shaft_1" content_type="model/stl" file="Shaft_1.stl" scale="0.001 0.001 0.001"/>
    <mesh name="Impact_Plate_1" content_type="model/stl" file="Impact_Plate_1.stl" scale="0.001 0.001 0.001"/>
    <mesh name="Slider_jig_1" content_type="model/stl" file="Slider_jig_1.stl" scale="0.001 0.001 0.001"/>
    <mesh name="Wall_1" content_type="model/stl" file="Wall_1.stl" scale="0.001 0.001 0.001"/>
    <mesh name="Slider1_1" content_type="model/stl" file="Slider1_1.stl" scale="0.001 0.001 0.001"/>
  </asset>

  <worldbody>
    <body name="base_link" pos="0 0 0">
      <geom type="mesh" rgba="0.7 0.7 0.7 1" mesh="base_link"/>
      <geom type="mesh" rgba="0.7 0.7 0.7 1" mesh="braket1_1"/>
      <geom type="mesh" rgba="0.7 0.7 0.7 1" mesh="braket2_1"/>
      <geom type="mesh" rgba="0.7 0.7 0.7 1" mesh="motor_1"/>
      <geom type="mesh" rgba="0.7 0.7 0.7 1" mesh="Slider_jig_1"/>
      <geom type="mesh" rgba="0.7 0.7 0.7 1" mesh="Slider1_1"/>
      <body name="Wall_1">
        <geom type="mesh" rgba="0.7 0.7 0.7 1" mesh="Wall_1"/>
      </body>
    </body>
    <body name="motor_shaft_1" pos="-0.063 0.085 0.05">
      <inertial pos="0.014137 0.00923579 0" quat="0.510125 0.489666 -0.510125 0.489666" mass="0.0393299" diaginertia="5.34022e-06 5.28299e-06 2.05723e-06"/>
      <joint name="Revolute 47" pos="0 0 0" axis="1 0 0"/>
      <geom pos="0.063 -0.085 -0.05" quat="1 0 0 0" type="mesh" rgba="0.7 0.7 0.7 1" mesh="motor_shaft_1"/>
      <geom pos="0.063 -0.085 -0.05" quat="1 0 0 0" type="mesh" rgba="0.7 0.7 0.7 1" mesh="Link1_1"/>
      <body name="Link2_1" pos="0.0195 0.02 0">
        <inertial pos="0.005 0.047 0" quat="0.707107 0.707107 0 0" mass="0.168204" diaginertia="0.000169 0.000165 7e-06"/>
        <joint name="Revolute 49" pos="0 0 0" axis="-1 0 0"/>
        <geom pos="0.0435 -0.105 -0.05" quat="1 0 0 0" type="mesh" rgba="0.7 0.7 0.7 1" mesh="Link2_1"/>
        <body name="Link3_1" pos="0 0.094 0">
          <inertial pos="-0.005 0.0111852 0" quat="0.707107 0.707107 0 0" mass="0.0459884" diaginertia="5e-06 4e-06 2e-06"/>
          <joint name="Revolute 50" pos="0 0 0" axis="-1 0 0"/>
          <geom pos="0.0435 -0.199 -0.05" quat="1 0 0 0" type="mesh" rgba="0.7 0.7 0.7 1" mesh="Link3_1"/>
        </body>
      </body>
    </body>
    <body name="Shaft_1" pos="-0.0485 0.2365 0.05">
      <inertial pos="-0.0872505 0.00603152 0" quat="0.435342 0.435342 0.557205 0.557205" mass="0.200519" diaginertia="0.000126812 9.4474e-05 5.06617e-05"/>
      <joint name="Slider 61" pos="0 0 0" axis="0 1 0" type="slide" actuatorfrcrange="-100 100"/>
      <geom pos="0.0485 -0.226 -0.05" quat="1 0 0 0" type="mesh" rgba="0.7 0.7 0.7 1" mesh="Shaft_1"/>
      <geom pos="0.0485 -0.2365 -0.05" quat="1 0 0 0" type="mesh" rgba="0.7 0.7 0.7 1" mesh="Impact_Plate_1"/>
    </body>
  </worldbody>
  
  <actuator>
    <motor name="torque_servo" joint="Revolute 47" ctrlrange="-10 10" ctrllimited="true" forcerange = "-3 3" gear = "1"/>
    <!-- <position name="position_servo" joint="Revolute 47" ctrlrange="-100 100" ctrllimited="true" kp="100"/>
     <velocity name="velocity_servo" joint="Revolute 47" kv="10"/> -->
  </actuator>
  
  <equality>
    <weld body1="Link3_1" body2 = "Shaft_1" anchor = "100 0 0" solref = "0.001 1" solimp = "0.99 0.999 0.001"/>
  </equality>
</mujoco>
