<?xml version="1.0" ?>
<!-- =================================================================================== -->
<!-- |    This document was autogenerated by xacro from /home/seongjin/Desktop/Seongjin/genesis_simulation_on_linux/My_asset/Crank_slider_system_V3_Pjoint_Posmod_description/urdf/Crank_slider_system_V3_Pjoint_Posmod.xacro | -->
<!-- |    EDITING THIS FILE BY HAND IS NOT RECOMMENDED                                 | -->
<!-- =================================================================================== -->
<robot name="Crank_slider_system_V3_Pjoint_Posmod">
  <material name="silver">
    <color rgba="0.700 0.700 0.700 1.000"/>
  </material>
  <transmission name="Revolute 47_tran">
    <type>transmission_interface/SimpleTransmission</type>
    <joint name="Revolute 47">
      <hardwareInterface>hardware_interface/EffortJointInterface</hardwareInterface>
    </joint>
    <actuator name="Revolute 47_actr">
      <hardwareInterface>hardware_interface/EffortJointInterface</hardwareInterface>
      <mechanicalReduction>1</mechanicalReduction>
    </actuator>
  </transmission>
  <transmission name="Revolute 49_tran">
    <type>transmission_interface/SimpleTransmission</type>
    <joint name="Revolute 49">
      <hardwareInterface>hardware_interface/EffortJointInterface</hardwareInterface>
    </joint>
    <actuator name="Revolute 49_actr">
      <hardwareInterface>hardware_interface/EffortJointInterface</hardwareInterface>
      <mechanicalReduction>1</mechanicalReduction>
    </actuator>
  </transmission>
  <transmission name="Revolute 50_tran">
    <type>transmission_interface/SimpleTransmission</type>
    <joint name="Revolute 50">
      <hardwareInterface>hardware_interface/EffortJointInterface</hardwareInterface>
    </joint>
    <actuator name="Revolute 50_actr">
      <hardwareInterface>hardware_interface/EffortJointInterface</hardwareInterface>
      <mechanicalReduction>1</mechanicalReduction>
    </actuator>
  </transmission>
  <transmission name="Slider 61_tran">
    <type>transmission_interface/SimpleTransmission</type>
    <joint name="Slider 61">
      <hardwareInterface>hardware_interface/EffortJointInterface</hardwareInterface>
    </joint>
    <actuator name="Slider 61_actr">
      <hardwareInterface>hardware_interface/EffortJointInterface</hardwareInterface>
      <mechanicalReduction>1</mechanicalReduction>
    </actuator>
  </transmission>
  <gazebo>
    <plugin filename="libgazebo_ros_control.so" name="control"/>
  </gazebo>
  <gazebo reference="base_link">
    <material>Gazebo/Silver</material>
    <mu1>0.2</mu1>
    <mu2>0.2</mu2>
    <selfCollide>true</selfCollide>
    <gravity>true</gravity>
  </gazebo>
  <gazebo reference="braket1_1">
    <material>Gazebo/Silver</material>
    <mu1>0.2</mu1>
    <mu2>0.2</mu2>
    <selfCollide>true</selfCollide>
  </gazebo>
  <gazebo reference="braket2_1">
    <material>Gazebo/Silver</material>
    <mu1>0.2</mu1>
    <mu2>0.2</mu2>
    <selfCollide>true</selfCollide>
  </gazebo>
  <gazebo reference="motor_1">
    <material>Gazebo/Silver</material>
    <mu1>0.2</mu1>
    <mu2>0.2</mu2>
    <selfCollide>true</selfCollide>
  </gazebo>
  <gazebo reference="motor_shaft_1">
    <material>Gazebo/Silver</material>
    <mu1>0.2</mu1>
    <mu2>0.2</mu2>
    <selfCollide>true</selfCollide>
  </gazebo>
  <gazebo reference="Link1_1">
    <material>Gazebo/Silver</material>
    <mu1>0.2</mu1>
    <mu2>0.2</mu2>
    <selfCollide>true</selfCollide>
  </gazebo>
  <gazebo reference="Link2_1">
    <material>Gazebo/Silver</material>
    <mu1>0.2</mu1>
    <mu2>0.2</mu2>
    <selfCollide>true</selfCollide>
  </gazebo>
  <gazebo reference="Link3_1">
    <material>Gazebo/Silver</material>
    <mu1>0.2</mu1>
    <mu2>0.2</mu2>
    <selfCollide>true</selfCollide>
  </gazebo>
  <gazebo reference="Shaft_1">
    <material>Gazebo/Silver</material>
    <mu1>0.2</mu1>
    <mu2>0.2</mu2>
    <selfCollide>true</selfCollide>
  </gazebo>
  <gazebo reference="Impact_Plate_1">
    <material>Gazebo/Silver</material>
    <mu1>0.2</mu1>
    <mu2>0.2</mu2>
    <selfCollide>true</selfCollide>
  </gazebo>
  <gazebo reference="Slider_jig_1">
    <material>Gazebo/Silver</material>
    <mu1>0.2</mu1>
    <mu2>0.2</mu2>
    <selfCollide>true</selfCollide>
  </gazebo>
  <gazebo reference="Wall_1">
    <material>Gazebo/Silver</material>
    <mu1>0.2</mu1>
    <mu2>0.2</mu2>
    <selfCollide>true</selfCollide>
  </gazebo>
  <gazebo reference="Shaft_1">
    <material>Gazebo/Silver</material>
    <mu1>0.2</mu1>
    <mu2>0.2</mu2>
    <selfCollide>true</selfCollide>
  </gazebo>
  <gazebo reference="Slider1_1">
    <material>Gazebo/Silver</material>
    <mu1>0.2</mu1>
    <mu2>0.2</mu2>
    <selfCollide>true</selfCollide>
  </gazebo>
  <link name="base_link">
    <inertial>
      <origin rpy="0 0 0" xyz="-0.06001305238884679 0.1999263664155562 0.0050000000000002135"/>
      <mass value="3.7636948268894805"/>
      <inertia ixx="0.05025" ixy="3e-06" ixz="0.0" iyy="0.004552" iyz="-0.0" izz="0.054739"/>
    </inertial>
    <visual>
      <origin rpy="0 0 0" xyz="0 0 0"/>
      <geometry>
        <mesh filename="../meshes/base_link.stl" scale="0.001 0.001 0.001"/>
      </geometry>
      <material name="silver"/>
    </visual>
    <collision>
      <origin rpy="0 0 0" xyz="0 0 0"/>
      <geometry>
        <mesh filename="../meshes/base_link.stl" scale="0.001 0.001 0.001"/>
      </geometry>
    </collision>
  </link>
  <link name="braket1_1">
    <inertial>
      <origin rpy="0 0 0" xyz="1.1102230246251565e-16 9.71445146547012e-17 0.005000000000000036"/>
      <mass value="0.28259999999999996"/>
      <inertia ixx="8.7e-05" ixy="0.0" ixz="0.0" iyy="8.7e-05" iyz="0.0" izz="0.00017"/>
    </inertial>
    <visual>
      <origin rpy="0 0 0" xyz="0.085 -0.085 -0.01"/>
      <geometry>
        <mesh filename="../meshes/braket1_1.stl" scale="0.001 0.001 0.001"/>
      </geometry>
      <material name="silver"/>
    </visual>
    <collision>
      <origin rpy="0 0 0" xyz="0.085 -0.085 -0.01"/>
      <geometry>
        <mesh filename="../meshes/braket1_1.stl" scale="0.001 0.001 0.001"/>
      </geometry>
    </collision>
  </link>
  <link name="braket2_1">
    <inertial>
      <origin rpy="0 0 0" xyz="1.942890293094024e-16 5.958400994821034e-10 0.03000000000000005"/>
      <mass value="0.24406640260831103"/>
      <inertia ixx="0.000167" ixy="0.0" ixz="-0.0" iyy="8.5e-05" iyz="0.0" izz="8.5e-05"/>
    </inertial>
    <visual>
      <origin rpy="0 0 0" xyz="0.06 -0.085 -0.02"/>
      <geometry>
        <mesh filename="../meshes/braket2_1.stl" scale="0.001 0.001 0.001"/>
      </geometry>
      <material name="silver"/>
    </visual>
    <collision>
      <origin rpy="0 0 0" xyz="0.06 -0.085 -0.02"/>
      <geometry>
        <mesh filename="../meshes/braket2_1.stl" scale="0.001 0.001 0.001"/>
      </geometry>
    </collision>
  </link>
  <link name="motor_1">
    <inertial>
      <origin rpy="0 0 0" xyz="-0.01971245258615248 1.016437115031188e-09 -7.402680003709694e-09"/>
      <mass value="0.5513081044550306"/>
      <inertia ixx="0.000156" ixy="0.0" ixz="-0.0" iyy="0.000154" iyz="-0.0" izz="0.000154"/>
    </inertial>
    <visual>
      <origin rpy="0 0 0" xyz="0.0655 -0.085 -0.05"/>
      <geometry>
        <mesh filename="../meshes/motor_1.stl" scale="0.001 0.001 0.001"/>
      </geometry>
      <material name="silver"/>
    </visual>
    <collision>
      <origin rpy="0 0 0" xyz="0.0655 -0.085 -0.05"/>
      <geometry>
        <mesh filename="../meshes/motor_1.stl" scale="0.001 0.001 0.001"/>
      </geometry>
    </collision>
  </link>
  <link name="motor_shaft_1">
    <inertial>
      <origin rpy="0 0 0" xyz="0.009750000000000002 5.96046795253713e-10 -5.228734112350253e-13"/>
      <mass value="0.0030056205965515235"/>
      <inertia ixx="0.0" ixy="0.0" ixz="0.0" iyy="0.0" iyz="-0.0" izz="0.0"/>
    </inertial>
    <visual>
      <origin rpy="0 0 0" xyz="0.063 -0.085 -0.05"/>
      <geometry>
        <mesh filename="../meshes/motor_shaft_1.stl" scale="0.001 0.001 0.001"/>
      </geometry>
      <material name="silver"/>
    </visual>
    <collision>
      <origin rpy="0 0 0" xyz="0.063 -0.085 -0.05"/>
      <geometry>
        <mesh filename="../meshes/motor_shaft_1.stl" scale="0.001 0.001 0.001"/>
      </geometry>
    </collision>
  </link>
  <link name="Link1_1">
    <inertial>
      <origin rpy="0 0 0" xyz="-0.005000000000000192 0.01000000059602442 2.636779683484747e-16"/>
      <mass value="0.03632431220866492"/>
      <inertia ixx="4e-06" ixy="0.0" ixz="0.0" iyy="1e-06" iyz="0.0" izz="4e-06"/>
    </inertial>
    <visual>
      <origin rpy="0 0 0" xyz="0.0435 -0.085 -0.05"/>
      <geometry>
        <mesh filename="../meshes/Link1_1.stl" scale="0.001 0.001 0.001"/>
      </geometry>
      <material name="silver"/>
    </visual>
    <collision>
      <origin rpy="0 0 0" xyz="0.0435 -0.085 -0.05"/>
      <geometry>
        <mesh filename="../meshes/Link1_1.stl" scale="0.001 0.001 0.001"/>
      </geometry>
    </collision>
  </link>
  <link name="Link2_1">
    <inertial>
      <origin rpy="0 0 0" xyz="0.004999999999999949 0.047000000596041244 5.273559366969494e-16"/>
      <mass value="0.1682043122086649"/>
      <inertia ixx="0.000169" ixy="0.0" ixz="0.0" iyy="7e-06" iyz="0.0" izz="0.000165"/>
    </inertial>
    <visual>
      <origin rpy="0 0 0" xyz="0.0435 -0.105 -0.05"/>
      <geometry>
        <mesh filename="../meshes/Link2_1.stl" scale="0.001 0.001 0.001"/>
      </geometry>
      <material name="silver"/>
    </visual>
    <collision>
      <origin rpy="0 0 0" xyz="0.0435 -0.105 -0.05"/>
      <geometry>
        <mesh filename="../meshes/Link2_1.stl" scale="0.001 0.001 0.001"/>
      </geometry>
    </collision>
  </link>
  <link name="Link3_1">
    <inertial>
      <origin rpy="0 0 0" xyz="-0.004999999999988507 0.011185192602428284 3.885780586188048e-16"/>
      <mass value="0.045988409039964616"/>
      <inertia ixx="5e-06" ixy="-0.0" ixz="0.0" iyy="2e-06" iyz="0.0" izz="4e-06"/>
    </inertial>
    <visual>
      <origin rpy="0 0 0" xyz="0.0435 -0.199 -0.05"/>
      <geometry>
        <mesh filename="../meshes/Link3_1.stl" scale="0.001 0.001 0.001"/>
      </geometry>
      <material name="silver"/>
    </visual>
    <collision>
      <origin rpy="0 0 0" xyz="0.0435 -0.199 -0.05"/>
      <geometry>
        <mesh filename="../meshes/Link3_1.stl" scale="0.001 0.001 0.001"/>
      </geometry>
    </collision>
  </link>
  <link name="Shaft_1">
    <inertial>
      <origin rpy="0 0 0" xyz="-1.6882328868206287e-14 0.04565824322633397 3.608224830031759e-16"/>
      <mass value="0.005039873731856857"/>
      <inertia ixx="4e-06" ixy="0.0" ixz="0.0" iyy="0.0" iyz="-0.0" izz="4e-06"/>
    </inertial>
    <visual>
      <origin rpy="0 0 0" xyz="0.0485 -0.226 -0.05"/>
      <geometry>
        <mesh filename="../meshes/Shaft_1.stl" scale="0.001 0.001 0.001"/>
      </geometry>
      <material name="silver"/>
    </visual>
    <collision>
      <origin rpy="0 0 0" xyz="0.0485 -0.226 -0.05"/>
      <geometry>
        <mesh filename="../meshes/Shaft_1.stl" scale="0.001 0.001 0.001"/>
      </geometry>
    </collision>
  </link>
  <link name="Impact_Plate_1">
    <inertial>
      <origin rpy="0 0 0" xyz="2.3592239273284576e-16 0.005009856778225408 1.734723475976807e-15"/>
      <mass value="0.19547932805216622"/>
      <inertia ixx="4.3e-05" ixy="0.0" ixz="-0.0" iyy="8.2e-05" iyz="0.0" izz="4.3e-05"/>
    </inertial>
    <visual>
      <origin rpy="0 0 0" xyz="0.0485 -0.326 -0.05"/>
      <geometry>
        <mesh filename="../meshes/Impact_Plate_1.stl" scale="0.001 0.001 0.001"/>
      </geometry>
      <material name="silver"/>
    </visual>
    <collision>
      <origin rpy="0 0 0" xyz="0.0485 -0.326 -0.05"/>
      <geometry>
        <mesh filename="../meshes/Impact_Plate_1.stl" scale="0.001 0.001 0.001"/>
      </geometry>
    </collision>
  </link>
  <link name="Slider_jig_1">
    <inertial>
      <origin rpy="0 0 0" xyz="2.2898349882893854e-16 5.960499316337575e-10 0.016376778097791242"/>
      <mass value="0.35259085195735623"/>
      <inertia ixx="8.6e-05" ixy="-0.0" ixz="0.0" iyy="6.2e-05" iyz="-0.0" izz="8.4e-05"/>
    </inertial>
    <visual>
      <origin rpy="0 0 0" xyz="0.0475 -0.258 -0.01"/>
      <geometry>
        <mesh filename="../meshes/Slider_jig_1.stl" scale="0.001 0.001 0.001"/>
      </geometry>
      <material name="silver"/>
    </visual>
    <collision>
      <origin rpy="0 0 0" xyz="0.0475 -0.258 -0.01"/>
      <geometry>
        <mesh filename="../meshes/Slider_jig_1.stl" scale="0.001 0.001 0.001"/>
      </geometry>
    </collision>
  </link>
  <link name="Wall_1">
    <inertial>
      <origin rpy="0 0 0" xyz="4.579669976578771e-16 -0.01371862673873725 0.026266919964917652"/>
      <mass value="1.240738012063854"/>
      <inertia ixx="0.001161" ixy="-0.0" ixz="-0.0" iyy="0.002257" iyz="0.000318" izz="0.001882"/>
    </inertial>
    <visual>
      <origin rpy="0 0 0" xyz="0.06 -0.369243 -0.01"/>
      <geometry>
        <mesh filename="../meshes/Wall_1.stl" scale="0.001 0.001 0.001"/>
      </geometry>
      <material name="silver"/>
    </visual>
    <collision>
      <origin rpy="0 0 0" xyz="0.06 -0.369243 -0.01"/>
      <geometry>
        <mesh filename="../meshes/Wall_1.stl" scale="0.001 0.001 0.001"/>
      </geometry>
    </collision>
  </link>
  <link name="Shaft_1">
    <inertial>
      <origin rpy="0 0 0" xyz="-1.6882328868206287e-14 0.035158243226333985 3.608224830031759e-16"/>
      <mass value="0.005039873731856857"/>
      <inertia ixx="4e-06" ixy="0.0" ixz="0.0" iyy="0.0" iyz="-0.0" izz="4e-06"/>
    </inertial>
    <visual>
      <origin rpy="0 0 0" xyz="0.0485 -0.2365 -0.05"/>
      <geometry>
        <mesh filename="../meshes/Shaft_1.stl" scale="0.001 0.001 0.001"/>
      </geometry>
      <material name="silver"/>
    </visual>
    <collision>
      <origin rpy="0 0 0" xyz="0.0485 -0.2365 -0.05"/>
      <geometry>
        <mesh filename="../meshes/Shaft_1.stl" scale="0.001 0.001 0.001"/>
      </geometry>
    </collision>
  </link>
  <link name="Slider1_1">
    <inertial>
      <origin rpy="0 0 0" xyz="-0.011863299551401321 0.014000000596053275 0.009240949156360236"/>
      <mass value="0.17824509933053143"/>
      <inertia ixx="3.2e-05" ixy="0.0" ixz="0.0" iyy="2.4e-05" iyz="0.0" izz="4.6e-05"/>
    </inertial>
    <visual>
      <origin rpy="0 0 0" xyz="0.0355 -0.244 -0.043"/>
      <geometry>
        <mesh filename="../meshes/Slider1_1.stl" scale="0.001 0.001 0.001"/>
      </geometry>
      <material name="silver"/>
    </visual>
    <collision>
      <origin rpy="0 0 0" xyz="0.0355 -0.244 -0.043"/>
      <geometry>
        <mesh filename="../meshes/Slider1_1.stl" scale="0.001 0.001 0.001"/>
      </geometry>
    </collision>
  </link>
  <joint name="Rigid 44" type="fixed">
    <origin rpy="0 0 0" xyz="-0.085 0.085 0.01"/>
    <parent link="base_link"/>
    <child link="braket1_1"/>
  </joint>
  <joint name="Rigid 45" type="fixed">
    <origin rpy="0 0 0" xyz="0.025 0.0 0.01"/>
    <parent link="braket1_1"/>
    <child link="braket2_1"/>
  </joint>
  <joint name="Rigid 46" type="fixed">
    <origin rpy="0 0 0" xyz="-0.0055 0.0 0.03"/>
    <parent link="braket2_1"/>
    <child link="motor_1"/>
  </joint>
  <joint name="Revolute 47" type="continuous">
    <origin rpy="0 0 0" xyz="0.0025 0.0 0.0"/>
    <parent link="motor_1"/>
    <child link="motor_shaft_1"/>
    <axis xyz="1.0 -0.0 0.0"/>
  </joint>
  <joint name="Rigid 48" type="fixed">
    <origin rpy="0 0 0" xyz="0.0195 0.0 0.0"/>
    <parent link="motor_shaft_1"/>
    <child link="Link1_1"/>
  </joint>
  <joint name="Revolute 49" type="continuous">
    <origin rpy="0 0 0" xyz="0.0 0.02 0.0"/>
    <parent link="Link1_1"/>
    <child link="Link2_1"/>
    <axis xyz="-1.0 0.0 -0.0"/>
  </joint>
  <joint name="Revolute 50" type="continuous">
    <origin rpy="0 0 0" xyz="0.0 0.094 0.0"/>
    <parent link="Link2_1"/>
    <child link="Link3_1"/>
    <axis xyz="-1.0 0.0 -0.0"/>
  </joint>
  <joint name="Rigid 51" type="fixed">
    <origin rpy="0 0 0" xyz="-0.005 0.0375 0.0"/>
    <parent link="Link3_1"/>
    <child link="Shaft_1"/>
  </joint>
  <joint name="Rigid 53" type="fixed">
    <origin rpy="0 0 0" xyz="0.0 0.0895 0.0"/>
    <parent link="Shaft_1"/>
    <child link="Impact_Plate_1"/>
  </joint>
  <joint name="Rigid 54" type="fixed">
    <origin rpy="0 0 0" xyz="-0.0475 0.258 0.01"/>
    <parent link="base_link"/>
    <child link="Slider_jig_1"/>
  </joint>
  <joint name="Rigid 55" type="fixed">
    <origin rpy="0 0 0" xyz="-0.06 0.369243 0.01"/>
    <parent link="base_link"/>
    <child link="Wall_1"/>
  </joint>
  <joint name="Slider 61" type="prismatic">
    <origin rpy="0 0 0" xyz="-0.013 -0.0075 0.007"/>
    <parent link="Slider1_1"/>
    <child link="Shaft_1"/>
    <axis xyz="0.0 1.0 0.0"/>
    <limit effort="100" lower="0.0" upper="0.0" velocity="100"/>
  </joint>
  <joint name="Rigid 62" type="fixed">
    <origin rpy="0 0 0" xyz="0.012 -0.014 0.033"/>
    <parent link="Slider_jig_1"/>
    <child link="Slider1_1"/>
  </joint>
</robot>
