<mujoco model="Crank_slider_system_V1_CoaCD">
  <default>
    <default class="visual2">
      <geom group="2" type="mesh" contype="0" conaffinity="0"/>
    </default>
    <default class="collision2">
      <geom group="3" type="mesh"/>
    </default>
  </default>
  <asset>
        <mesh name="Impact_Plate_1" file="/home/seongjin/Desktop/Seongjin/genesis_simulation_on_linux/My_asset/Crank_slider_system_V1_description/urdf/Impact_Plate_1.obj" scale="0.001 0.001 0.001"/>
        <mesh name="Impact_Plate_1_collision_(1)" file="/home/seongjin/Desktop/Seongjin/genesis_simulation_on_linux/My_asset/Crank_slider_system_V1_description/urdf/Impact_Plate_1_collision_(1).obj" scale="0.001 0.001 0.001"/>
        <mesh name="Impact_Plate_1_collision_(10)" file="/home/seongjin/Desktop/Seongjin/genesis_simulation_on_linux/My_asset/Crank_slider_system_V1_description/urdf/Impact_Plate_1_collision_(10).obj" scale="0.001 0.001 0.001"/>
        <mesh name="Impact_Plate_1_collision_(11)" file="/home/seongjin/Desktop/Seongjin/genesis_simulation_on_linux/My_asset/Crank_slider_system_V1_description/urdf/Impact_Plate_1_collision_(11).obj" scale="0.001 0.001 0.001"/>
        <mesh name="Impact_Plate_1_collision_(12)" file="/home/seongjin/Desktop/Seongjin/genesis_simulation_on_linux/My_asset/Crank_slider_system_V1_description/urdf/Impact_Plate_1_collision_(12).obj" scale="0.001 0.001 0.001"/>
        <mesh name="Impact_Plate_1_collision_(13)" file="/home/seongjin/Desktop/Seongjin/genesis_simulation_on_linux/My_asset/Crank_slider_system_V1_description/urdf/Impact_Plate_1_collision_(13).obj" scale="0.001 0.001 0.001"/>
        <mesh name="Impact_Plate_1_collision_(14)" file="/home/seongjin/Desktop/Seongjin/genesis_simulation_on_linux/My_asset/Crank_slider_system_V1_description/urdf/Impact_Plate_1_collision_(14).obj" scale="0.001 0.001 0.001"/>
        <mesh name="Impact_Plate_1_collision_(15)" file="/home/seongjin/Desktop/Seongjin/genesis_simulation_on_linux/My_asset/Crank_slider_system_V1_description/urdf/Impact_Plate_1_collision_(15).obj" scale="0.001 0.001 0.001"/>
        <mesh name="Impact_Plate_1_collision_(2)" file="/home/seongjin/Desktop/Seongjin/genesis_simulation_on_linux/My_asset/Crank_slider_system_V1_description/urdf/Impact_Plate_1_collision_(2).obj" scale="0.001 0.001 0.001"/>
        <mesh name="Impact_Plate_1_collision_(3)" file="/home/seongjin/Desktop/Seongjin/genesis_simulation_on_linux/My_asset/Crank_slider_system_V1_description/urdf/Impact_Plate_1_collision_(3).obj" scale="0.001 0.001 0.001"/>
        <mesh name="Impact_Plate_1_collision_(4)" file="/home/seongjin/Desktop/Seongjin/genesis_simulation_on_linux/My_asset/Crank_slider_system_V1_description/urdf/Impact_Plate_1_collision_(4).obj" scale="0.001 0.001 0.001"/>
        <mesh name="Impact_Plate_1_collision_(5)" file="/home/seongjin/Desktop/Seongjin/genesis_simulation_on_linux/My_asset/Crank_slider_system_V1_description/urdf/Impact_Plate_1_collision_(5).obj" scale="0.001 0.001 0.001"/>
        <mesh name="Impact_Plate_1_collision_(6)" file="/home/seongjin/Desktop/Seongjin/genesis_simulation_on_linux/My_asset/Crank_slider_system_V1_description/urdf/Impact_Plate_1_collision_(6).obj" scale="0.001 0.001 0.001"/>
        <mesh name="Impact_Plate_1_collision_(7)" file="/home/seongjin/Desktop/Seongjin/genesis_simulation_on_linux/My_asset/Crank_slider_system_V1_description/urdf/Impact_Plate_1_collision_(7).obj" scale="0.001 0.001 0.001"/>
        <mesh name="Impact_Plate_1_collision_(8)" file="/home/seongjin/Desktop/Seongjin/genesis_simulation_on_linux/My_asset/Crank_slider_system_V1_description/urdf/Impact_Plate_1_collision_(8).obj" scale="0.001 0.001 0.001"/>
        <mesh name="Impact_Plate_1_collision_(9)" file="/home/seongjin/Desktop/Seongjin/genesis_simulation_on_linux/My_asset/Crank_slider_system_V1_description/urdf/Impact_Plate_1_collision_(9).obj" scale="0.001 0.001 0.001"/>
        <mesh name="Link1_1" file="/home/seongjin/Desktop/Seongjin/genesis_simulation_on_linux/My_asset/Crank_slider_system_V1_description/urdf/Link1_1.obj" scale="0.001 0.001 0.001"/>
        <mesh name="Link1_1_collision_(1)" file="/home/seongjin/Desktop/Seongjin/genesis_simulation_on_linux/My_asset/Crank_slider_system_V1_description/urdf/Link1_1_collision_(1).obj" scale="0.001 0.001 0.001"/>
        <mesh name="Link1_1_collision_(2)" file="/home/seongjin/Desktop/Seongjin/genesis_simulation_on_linux/My_asset/Crank_slider_system_V1_description/urdf/Link1_1_collision_(2).obj" scale="0.001 0.001 0.001"/>
        <mesh name="Link1_1_collision_(3)" file="/home/seongjin/Desktop/Seongjin/genesis_simulation_on_linux/My_asset/Crank_slider_system_V1_description/urdf/Link1_1_collision_(3).obj" scale="0.001 0.001 0.001"/>
        <mesh name="Link1_1_collision_(4)" file="/home/seongjin/Desktop/Seongjin/genesis_simulation_on_linux/My_asset/Crank_slider_system_V1_description/urdf/Link1_1_collision_(4).obj" scale="0.001 0.001 0.001"/>
        <mesh name="Link1_1_collision_(5)" file="/home/seongjin/Desktop/Seongjin/genesis_simulation_on_linux/My_asset/Crank_slider_system_V1_description/urdf/Link1_1_collision_(5).obj" scale="0.001 0.001 0.001"/>
        <mesh name="Link1_1_collision_(6)" file="/home/seongjin/Desktop/Seongjin/genesis_simulation_on_linux/My_asset/Crank_slider_system_V1_description/urdf/Link1_1_collision_(6).obj" scale="0.001 0.001 0.001"/>
        <mesh name="Link1_1_collision_(7)" file="/home/seongjin/Desktop/Seongjin/genesis_simulation_on_linux/My_asset/Crank_slider_system_V1_description/urdf/Link1_1_collision_(7).obj" scale="0.001 0.001 0.001"/>
        <mesh name="Link1_1_collision_(8)" file="/home/seongjin/Desktop/Seongjin/genesis_simulation_on_linux/My_asset/Crank_slider_system_V1_description/urdf/Link1_1_collision_(8).obj" scale="0.001 0.001 0.001"/>
        <mesh name="Link2_1" file="/home/seongjin/Desktop/Seongjin/genesis_simulation_on_linux/My_asset/Crank_slider_system_V1_description/urdf/Link2_1.obj" scale="0.001 0.001 0.001"/>
        <mesh name="Link2_1_collision_(1)" file="/home/seongjin/Desktop/Seongjin/genesis_simulation_on_linux/My_asset/Crank_slider_system_V1_description/urdf/Link2_1_collision_(1).obj" scale="0.001 0.001 0.001"/>
        <mesh name="Link3_1" file="/home/seongjin/Desktop/Seongjin/genesis_simulation_on_linux/My_asset/Crank_slider_system_V1_description/urdf/Link3_1.obj" scale="0.001 0.001 0.001"/>
        <mesh name="Link3_1_collision_(1)" file="/home/seongjin/Desktop/Seongjin/genesis_simulation_on_linux/My_asset/Crank_slider_system_V1_description/urdf/Link3_1_collision_(1).obj" scale="0.001 0.001 0.001"/>
        <mesh name="Link3_1_collision_(10)" file="/home/seongjin/Desktop/Seongjin/genesis_simulation_on_linux/My_asset/Crank_slider_system_V1_description/urdf/Link3_1_collision_(10).obj" scale="0.001 0.001 0.001"/>
        <mesh name="Link3_1_collision_(11)" file="/home/seongjin/Desktop/Seongjin/genesis_simulation_on_linux/My_asset/Crank_slider_system_V1_description/urdf/Link3_1_collision_(11).obj" scale="0.001 0.001 0.001"/>
        <mesh name="Link3_1_collision_(12)" file="/home/seongjin/Desktop/Seongjin/genesis_simulation_on_linux/My_asset/Crank_slider_system_V1_description/urdf/Link3_1_collision_(12).obj" scale="0.001 0.001 0.001"/>
        <mesh name="Link3_1_collision_(13)" file="/home/seongjin/Desktop/Seongjin/genesis_simulation_on_linux/My_asset/Crank_slider_system_V1_description/urdf/Link3_1_collision_(13).obj" scale="0.001 0.001 0.001"/>
        <mesh name="Link3_1_collision_(14)" file="/home/seongjin/Desktop/Seongjin/genesis_simulation_on_linux/My_asset/Crank_slider_system_V1_description/urdf/Link3_1_collision_(14).obj" scale="0.001 0.001 0.001"/>
        <mesh name="Link3_1_collision_(2)" file="/home/seongjin/Desktop/Seongjin/genesis_simulation_on_linux/My_asset/Crank_slider_system_V1_description/urdf/Link3_1_collision_(2).obj" scale="0.001 0.001 0.001"/>
        <mesh name="Link3_1_collision_(3)" file="/home/seongjin/Desktop/Seongjin/genesis_simulation_on_linux/My_asset/Crank_slider_system_V1_description/urdf/Link3_1_collision_(3).obj" scale="0.001 0.001 0.001"/>
        <mesh name="Link3_1_collision_(4)" file="/home/seongjin/Desktop/Seongjin/genesis_simulation_on_linux/My_asset/Crank_slider_system_V1_description/urdf/Link3_1_collision_(4).obj" scale="0.001 0.001 0.001"/>
        <mesh name="Link3_1_collision_(5)" file="/home/seongjin/Desktop/Seongjin/genesis_simulation_on_linux/My_asset/Crank_slider_system_V1_description/urdf/Link3_1_collision_(5).obj" scale="0.001 0.001 0.001"/>
        <mesh name="Link3_1_collision_(6)" file="/home/seongjin/Desktop/Seongjin/genesis_simulation_on_linux/My_asset/Crank_slider_system_V1_description/urdf/Link3_1_collision_(6).obj" scale="0.001 0.001 0.001"/>
        <mesh name="Link3_1_collision_(7)" file="/home/seongjin/Desktop/Seongjin/genesis_simulation_on_linux/My_asset/Crank_slider_system_V1_description/urdf/Link3_1_collision_(7).obj" scale="0.001 0.001 0.001"/>
        <mesh name="Link3_1_collision_(8)" file="/home/seongjin/Desktop/Seongjin/genesis_simulation_on_linux/My_asset/Crank_slider_system_V1_description/urdf/Link3_1_collision_(8).obj" scale="0.001 0.001 0.001"/>
        <mesh name="Link3_1_collision_(9)" file="/home/seongjin/Desktop/Seongjin/genesis_simulation_on_linux/My_asset/Crank_slider_system_V1_description/urdf/Link3_1_collision_(9).obj" scale="0.001 0.001 0.001"/>
        <mesh name="Shaft_1" file="/home/seongjin/Desktop/Seongjin/genesis_simulation_on_linux/My_asset/Crank_slider_system_V1_description/urdf/Shaft_1.obj" scale="0.001 0.001 0.001"/>
        <mesh name="Shaft_1_collision_(1)" file="/home/seongjin/Desktop/Seongjin/genesis_simulation_on_linux/My_asset/Crank_slider_system_V1_description/urdf/Shaft_1_collision_(1).obj" scale="0.001 0.001 0.001"/>
        <mesh name="Shaft_1_collision_(2)" file="/home/seongjin/Desktop/Seongjin/genesis_simulation_on_linux/My_asset/Crank_slider_system_V1_description/urdf/Shaft_1_collision_(2).obj" scale="0.001 0.001 0.001"/>
        <mesh name="Shaft_1_collision_(3)" file="/home/seongjin/Desktop/Seongjin/genesis_simulation_on_linux/My_asset/Crank_slider_system_V1_description/urdf/Shaft_1_collision_(3).obj" scale="0.001 0.001 0.001"/>
        <mesh name="Wall_1" file="/home/seongjin/Desktop/Seongjin/genesis_simulation_on_linux/My_asset/Crank_slider_system_V1_description/urdf/Wall_1.obj" scale="0.001 0.001 0.001"/>
        <mesh name="Wall_1_collision_(1)" file="/home/seongjin/Desktop/Seongjin/genesis_simulation_on_linux/My_asset/Crank_slider_system_V1_description/urdf/Wall_1_collision_(1).obj" scale="0.001 0.001 0.001"/>
        <mesh name="Wall_1_collision_(2)" file="/home/seongjin/Desktop/Seongjin/genesis_simulation_on_linux/My_asset/Crank_slider_system_V1_description/urdf/Wall_1_collision_(2).obj" scale="0.001 0.001 0.001"/>
        <mesh name="Wall_1_collision_(3)" file="/home/seongjin/Desktop/Seongjin/genesis_simulation_on_linux/My_asset/Crank_slider_system_V1_description/urdf/Wall_1_collision_(3).obj" scale="0.001 0.001 0.001"/>
        <mesh name="base_link" file="/home/seongjin/Desktop/Seongjin/genesis_simulation_on_linux/My_asset/Crank_slider_system_V1_description/urdf/base_link.obj" scale="0.001 0.001 0.001"/>
        <mesh name="base_link_collision_(1)" file="/home/seongjin/Desktop/Seongjin/genesis_simulation_on_linux/My_asset/Crank_slider_system_V1_description/urdf/base_link_collision_(1).obj" scale="0.001 0.001 0.001"/>
        <mesh name="base_link_collision_(2)" file="/home/seongjin/Desktop/Seongjin/genesis_simulation_on_linux/My_asset/Crank_slider_system_V1_description/urdf/base_link_collision_(2).obj" scale="0.001 0.001 0.001"/>
        <mesh name="braket1_1" file="/home/seongjin/Desktop/Seongjin/genesis_simulation_on_linux/My_asset/Crank_slider_system_V1_description/urdf/braket1_1.obj" scale="0.001 0.001 0.001"/>
        <mesh name="braket1_1_collision_(1)" file="/home/seongjin/Desktop/Seongjin/genesis_simulation_on_linux/My_asset/Crank_slider_system_V1_description/urdf/braket1_1_collision_(1).obj" scale="0.001 0.001 0.001"/>
        <mesh name="braket2_1" file="/home/seongjin/Desktop/Seongjin/genesis_simulation_on_linux/My_asset/Crank_slider_system_V1_description/urdf/braket2_1.obj" scale="0.001 0.001 0.001"/>
        <mesh name="braket2_1_collision_(1)" file="/home/seongjin/Desktop/Seongjin/genesis_simulation_on_linux/My_asset/Crank_slider_system_V1_description/urdf/braket2_1_collision_(1).obj" scale="0.001 0.001 0.001"/>
        <mesh name="braket2_1_collision_(2)" file="/home/seongjin/Desktop/Seongjin/genesis_simulation_on_linux/My_asset/Crank_slider_system_V1_description/urdf/braket2_1_collision_(2).obj" scale="0.001 0.001 0.001"/>
        <mesh name="braket2_1_collision_(3)" file="/home/seongjin/Desktop/Seongjin/genesis_simulation_on_linux/My_asset/Crank_slider_system_V1_description/urdf/braket2_1_collision_(3).obj" scale="0.001 0.001 0.001"/>
        <mesh name="braket2_1_collision_(4)" file="/home/seongjin/Desktop/Seongjin/genesis_simulation_on_linux/My_asset/Crank_slider_system_V1_description/urdf/braket2_1_collision_(4).obj" scale="0.001 0.001 0.001"/>
        <mesh name="braket2_1_collision_(5)" file="/home/seongjin/Desktop/Seongjin/genesis_simulation_on_linux/My_asset/Crank_slider_system_V1_description/urdf/braket2_1_collision_(5).obj" scale="0.001 0.001 0.001"/>
        <mesh name="braket2_1_collision_(6)" file="/home/seongjin/Desktop/Seongjin/genesis_simulation_on_linux/My_asset/Crank_slider_system_V1_description/urdf/braket2_1_collision_(6).obj" scale="0.001 0.001 0.001"/>
        <mesh name="braket2_1_collision_(7)" file="/home/seongjin/Desktop/Seongjin/genesis_simulation_on_linux/My_asset/Crank_slider_system_V1_description/urdf/braket2_1_collision_(7).obj" scale="0.001 0.001 0.001"/>
        <mesh name="braket2_1_collision_(8)" file="/home/seongjin/Desktop/Seongjin/genesis_simulation_on_linux/My_asset/Crank_slider_system_V1_description/urdf/braket2_1_collision_(8).obj" scale="0.001 0.001 0.001"/>
        <mesh name="braket2_1_collision_(9)" file="/home/seongjin/Desktop/Seongjin/genesis_simulation_on_linux/My_asset/Crank_slider_system_V1_description/urdf/braket2_1_collision_(9).obj" scale="0.001 0.001 0.001"/>
        <mesh name="empty_box" file="/home/seongjin/Desktop/Seongjin/genesis_simulation_on_linux/My_asset/Crank_slider_system_V1_description/urdf/empty_box.obj" scale="0.001 0.001 0.001"/>
        <mesh name="motor_1" file="/home/seongjin/Desktop/Seongjin/genesis_simulation_on_linux/My_asset/Crank_slider_system_V1_description/urdf/motor_1.obj" scale="0.001 0.001 0.001"/>
        <mesh name="motor_1_collision_(1)" file="/home/seongjin/Desktop/Seongjin/genesis_simulation_on_linux/My_asset/Crank_slider_system_V1_description/urdf/motor_1_collision_(1).obj" scale="0.001 0.001 0.001"/>
        <mesh name="motor_1_collision_(2)" file="/home/seongjin/Desktop/Seongjin/genesis_simulation_on_linux/My_asset/Crank_slider_system_V1_description/urdf/motor_1_collision_(2).obj" scale="0.001 0.001 0.001"/>
        <mesh name="motor_shaft_1" file="/home/seongjin/Desktop/Seongjin/genesis_simulation_on_linux/My_asset/Crank_slider_system_V1_description/urdf/motor_shaft_1.obj" scale="0.001 0.001 0.001"/>
        <mesh name="motor_shaft_1_collision_(1)" file="/home/seongjin/Desktop/Seongjin/genesis_simulation_on_linux/My_asset/Crank_slider_system_V1_description/urdf/motor_shaft_1_collision_(1).obj" scale="0.001 0.001 0.001"/>
  </asset>
  <worldbody>
    <body>
        
        <geom type="mesh" rgba="0.7 0.7 0.7 1" mesh="base_link"/>
        <geom type="mesh" rgba="0.7 0.7 0.7 1" mesh="base_link_collision_(1)"/>
        <geom type="mesh" rgba="0.7 0.7 0.7 1" mesh="base_link_collision_(2)"/>
        
        <geom type = "mesh" rgba="0.7 0.7 0.7 1" mesh="braket1_1"/>
        <geom type = "mesh" rgba="0.7 0.7 0.7 1" mesh="braket1_1_collision_(1)"/>

        <geom type = "mesh" rgba="0.7 0.7 0.7 1" mesh="braket2_1"/>
        <geom type = "mesh" rgba="0.7 0.7 0.7 1" mesh="braket2_1_collision_(1)"/>
        <geom type = "mesh" rgba="0.7 0.7 0.7 1" mesh="braket2_1_collision_(2)"/>
        <geom type = "mesh" rgba="0.7 0.7 0.7 1" mesh="braket2_1_collision_(3)"/>
        <geom type = "mesh" rgba="0.7 0.7 0.7 1" mesh="braket2_1_collision_(4)"/>
        <geom type = "mesh" rgba="0.7 0.7 0.7 1" mesh="braket2_1_collision_(5)"/>
        <geom type = "mesh" rgba="0.7 0.7 0.7 1" mesh="braket2_1_collision_(6)"/>
        <geom type = "mesh" rgba="0.7 0.7 0.7 1" mesh="braket2_1_collision_(7)"/>
        <geom type = "mesh" rgba="0.7 0.7 0.7 1" mesh="braket2_1_collision_(8)"/>
        <geom type = "mesh" rgba="0.7 0.7 0.7 1" mesh="braket2_1_collision_(9)"/>
        
        <geom type="mesh" rgba="0.7 0.7 0.7 1" mesh="motor_1"/>
        <geom type="mesh" rgba="0.7 0.7 0.7 1" mesh="motor_1_collision_(1)"/>
        <geom type="mesh" rgba="0.7 0.7 0.7 1" mesh="motor_1_collision_(2)"/>

        <geom type="mesh" rgba="0.7 0.7 0.7 1" mesh="Wall_1"/>
        <geom type="mesh" rgba="0.7 0.7 0.7 1" mesh="Wall_1_collision_(1)"/>
        <geom type="mesh" rgba="0.7 0.7 0.7 1" mesh="Wall_1_collision_(2)"/>
        <geom type="mesh" rgba="0.7 0.7 0.7 1" mesh="Wall_1_collision_(3)"/>
    </body>

    <body name="motor_shaft_1" pos="0.11 0.05 -0.163">
      <inertial pos="0.0272456 0 -0.00387279" quat="0.438592 0.554651 0.554651 0.438592" mass="0.0393299" diaginertia="8.01969e-06 7.70194e-06 2.31775e-06"/>
      <joint name="Revolute 47" pos="0 0 0" axis="0 0 1"/>
      <geom pos="-0.11 -0.05 0.163" type="mesh" rgba="0.7 0.7 0.7 1" mesh="motor_shaft_1"/>
      <geom pos="-0.11 -0.05 0.163" type="mesh" rgba="0.7 0.7 0.7 1" mesh="motor_shaft_1_collision_(1)"/>
      <geom pos="-0.11 -0.05 0.163" quat="1 0 0 0" type="mesh" rgba="0.7 0.7 0.7 1" mesh="Link1_1"/>
      <geom pos="-0.11 -0.05 0.163" quat="1 0 0 0" type="mesh" rgba="0.7 0.7 0.7 1" mesh="Link1_1_collision_(1)"/>
      <geom pos="-0.11 -0.05 0.163" quat="1 0 0 0" type="mesh" rgba="0.7 0.7 0.7 1" mesh="Link1_1_collision_(2)"/>
        <geom pos="-0.11 -0.05 0.163" quat="1 0 0 0" type="mesh" rgba="0.7 0.7 0.7 1" mesh="Link1_1_collision_(3)"/>
        <geom pos="-0.11 -0.05 0.163" quat="1 0 0 0" type="mesh" rgba="0.7 0.7 0.7 1" mesh="Link1_1_collision_(4)"/>
        <geom pos="-0.11 -0.05 0.163" quat="1 0 0 0" type="mesh" rgba="0.7 0.7 0.7 1" mesh="Link1_1_collision_(5)"/>
        <geom pos="-0.11 -0.05 0.163" quat="1 0 0 0" type="mesh" rgba="0.7 0.7 0.7 1" mesh="Link1_1_collision_(6)"/>
        <geom pos="-0.11 -0.05 0.163" quat="1 0 0 0" type="mesh" rgba="0.7 0.7 0.7 1" mesh="Link1_1_collision_(7)"/>
        <geom pos="-0.11 -0.05 0.163" quat="1 0 0 0" type="mesh" rgba="0.7 0.7 0.7 1" mesh="Link1_1_collision_(8)"/>
      <body name="Link2_1" pos="0.02 0 0.0195">
        <inertial pos="0.047 0 0.005" quat="0 0.707107 0 0.707107" mass="0.168204" diaginertia="0.000169 0.000165 7e-06"/>
        <joint name="Revolute 49" range = "-0 0" pos="0 0 0" axis="0 0 -1"/>
        <geom pos="-0.13 -0.05 0.1435" quat="1 0 0 0" type="mesh" rgba="0.7 0.7 0.7 1" mesh="Link2_1"/>
        <body name="Link3_1" pos="0.094 0 0">
          <inertial pos="0.107601 0.000766691 -0.00489777" quat="-0.0322869 0.706513 -0.0494 0.705235" mass="0.246508" diaginertia="0.00062561 0.000617884 9.1756e-05"/>
          <joint name="Revolute 50" pos="0 0 0" axis="0 0 -1"/>
          <geom pos="-0.224 -0.05 0.1435" quat="1 0 0 0" type="mesh" rgba="0.7 0.7 0.7 1" mesh="Link3_1"/>
          <geom pos="-0.224 -0.05 0.1435" quat="1 0 0 0" type="mesh" rgba="0.7 0.7 0.7 1" mesh="Link3_1_collision_(1)"/>
          <geom pos="-0.224 -0.05 0.1435" quat="1 0 0 0" type="mesh" rgba="0.7 0.7 0.7 1" mesh="Link3_1_collision_(2)"/>
          <geom pos="-0.224 -0.05 0.1435" quat="1 0 0 0" type="mesh" rgba="0.7 0.7 0.7 1" mesh="Link3_1_collision_(3)"/>
          <geom pos="-0.224 -0.05 0.1435" quat="1 0 0 0" type="mesh" rgba="0.7 0.7 0.7 1" mesh="Link3_1_collision_(4)"/>
          <geom pos="-0.224 -0.05 0.1435" quat="1 0 0 0" type="mesh" rgba="0.7 0.7 0.7 1" mesh="Link3_1_collision_(5)"/>
          <geom pos="-0.224 -0.05 0.1435" quat="1 0 0 0" type="mesh" rgba="0.7 0.7 0.7 1" mesh="Link3_1_collision_(6)"/>
          <geom pos="-0.224 -0.05 0.1435" quat="1 0 0 0" type="mesh" rgba="0.7 0.7 0.7 1" mesh="Link3_1_collision_(7)"/>
          <geom pos="-0.224 -0.05 0.1435" quat="1 0 0 0" type="mesh" rgba="0.7 0.7 0.7 1" mesh="Link3_1_collision_(8)"/>
          <geom pos="-0.224 -0.05 0.1435" quat="1 0 0 0" type="mesh" rgba="0.7 0.7 0.7 1" mesh="Link3_1_collision_(9)"/>
          <geom pos="-0.224 -0.05 0.1435" quat="1 0 0 0" type="mesh" rgba="0.7 0.7 0.7 1" mesh="Link3_1_collision_(10)"/>
          <geom pos="-0.224 -0.05 0.1435" quat="1 0 0 0" type="mesh" rgba="0.7 0.7 0.7 1" mesh="Link3_1_collision_(11)"/>
          <geom pos="-0.224 -0.05 0.1435" quat="1 0 0 0" type="mesh" rgba="0.7 0.7 0.7 1" mesh="Link3_1_collision_(12)"/>
          <geom pos="-0.224 -0.05 0.1435" quat="1 0 0 0" type="mesh" rgba="0.7 0.7 0.7 1" mesh="Link3_1_collision_(13)"/>
          <geom pos="-0.224 -0.05 0.1435" quat="1 0 0 0" type="mesh" rgba="0.7 0.7 0.7 1" mesh="Link3_1_collision_(14)"/>
          <geom pos="-0.224 -0.05 0.1435" quat="1 0 0 0" type="mesh" rgba="0.7 0.7 0.7 1" mesh="Shaft_1"/>
          <geom pos="-0.224 -0.05 0.1435" quat="1 0 0 0" type="mesh" rgba="0.7 0.7 0.7 1" mesh="Shaft_1_collision_(1)"/>
          <geom pos="-0.224 -0.05 0.1435" quat="1 0 0 0" type="mesh" rgba="0.7 0.7 0.7 1" mesh="Shaft_1_collision_(2)"/>
          <geom pos="-0.224 -0.05 0.1435" quat="1 0 0 0" type="mesh" rgba="0.7 0.7 0.7 1" mesh="Shaft_1_collision_(3)"/>
          <geom pos="-0.224 -0.05 0.1435" type="mesh" rgba="0.7 0.7 0.7 1" mesh="Impact_Plate_1"/>
          <geom pos="-0.224 -0.05 0.1435" type="mesh" rgba="0.7 0.7 0.7 1" mesh="Impact_Plate_1_collision_(1)"/>
          <geom pos="-0.224 -0.05 0.1435" type="mesh" rgba="0.7 0.7 0.7 1" mesh="Impact_Plate_1_collision_(2)"/>
          <geom pos="-0.224 -0.05 0.1435" type="mesh" rgba="0.7 0.7 0.7 1" mesh="Impact_Plate_1_collision_(3)"/>
          <geom pos="-0.224 -0.05 0.1435" type="mesh" rgba="0.7 0.7 0.7 1" mesh="Impact_Plate_1_collision_(4)"/>
          <geom pos="-0.224 -0.05 0.1435" type="mesh" rgba="0.7 0.7 0.7 1" mesh="Impact_Plate_1_collision_(5)"/>
          <geom pos="-0.224 -0.05 0.1435" type="mesh" rgba="0.7 0.7 0.7 1" mesh="Impact_Plate_1_collision_(6)"/>
          <geom pos="-0.224 -0.05 0.1435" type="mesh" rgba="0.7 0.7 0.7 1" mesh="Impact_Plate_1_collision_(7)"/>
          <geom pos="-0.224 -0.05 0.1435" type="mesh" rgba="0.7 0.7 0.7 1" mesh="Impact_Plate_1_collision_(8)"/>
          <geom pos="-0.224 -0.05 0.1435" type="mesh" rgba="0.7 0.7 0.7 1" mesh="Impact_Plate_1_collision_(9)"/>
          <geom pos="-0.224 -0.05 0.1435" type="mesh" rgba="0.7 0.7 0.7 1" mesh="Impact_Plate_1_collision_(10)"/>
          <geom pos="-0.224 -0.05 0.1435" type="mesh" rgba="0.7 0.7 0.7 1" mesh="Impact_Plate_1_collision_(11)"/>
          <geom pos="-0.224 -0.05 0.1435" type="mesh" rgba="0.7 0.7 0.7 1" mesh="Impact_Plate_1_collision_(12)"/>
          <geom pos="-0.224 -0.05 0.1435" type="mesh" rgba="0.7 0.7 0.7 1" mesh="Impact_Plate_1_collision_(13)"/>
          <geom pos="-0.224 -0.05 0.1435" type="mesh" rgba="0.7 0.7 0.7 1" mesh="Impact_Plate_1_collision_(14)"/>
          <geom pos="-0.224 -0.05 0.1435" type="mesh" rgba="0.7 0.7 0.7 1" mesh="Impact_Plate_1_collision_(15)"/>
        </body>
      </body>
    </body>
  </worldbody>
</mujoco>