<mujoco model="Crank_slider_system_V1">
  <compiler angle="radian"/>

  <asset>
    <mesh name="base_link" content_type="model/stl" file="base_link.stl" scale="0.001 0.001 0.001"/>
    <mesh name="braket1_1" content_type="model/stl" file="braket1_1.stl" scale="0.001 0.001 0.001"/>
    <mesh name="braket2_1" content_type="model/stl" file="braket2_1.stl" scale="0.001 0.001 0.001"/>
    <mesh name="motor_1" content_type="model/stl" file="motor_1.stl" scale="0.001 0.001 0.001"/>
    <mesh name="motor_shaft_1" content_type="model/stl" file="motor_shaft_1.stl" scale="0.001 0.001 0.001"/>
    <mesh name="Link1_1" content_type="model/stl" file="Link1_1.stl" scale="0.001 0.001 0.001"/>
    <mesh name="Link2_1" content_type="model/stl" file="Link2_1.stl" scale="0.001 0.001 0.001"/>
    <mesh name="Link3_1" content_type="model/stl" file="Link3_1.stl" scale="0.001 0.001 0.001"/>
    <mesh name="Shaft_1" content_type="model/stl" file="Shaft_1.stl" scale="0.001 0.001 0.001"/>
    <mesh name="Impact_Plate_1" content_type="model/stl" file="Impact_Plate_1.stl" scale="0.001 0.001 0.001"/>
    <mesh name="Wall_1" content_type="model/stl" file="Wall_1.stl" scale="0.001 0.001 0.001"/>
  </asset>

  <worldbody>
    <geom type="mesh" rgba="0.7 0.7 0.7 1" mesh="base_link"/>
    <geom type="mesh" rgba="0.7 0.7 0.7 1" mesh="braket1_1"/>
    <geom type="mesh" rgba="0.7 0.7 0.7 1" mesh="braket2_1"/>
    <geom type="mesh" rgba="0.7 0.7 0.7 1" mesh="motor_1"/>
    <geom type="mesh" rgba="0.7 0.7 0.7 1" mesh="Wall_1"/>
    <body name="motor_shaft_1" pos="0.11 0.05 -0.163">
      <inertial pos="0.0272456 0 -0.00387279" quat="0.438592 0.554651 0.554651 0.438592" mass="0.0393299" diaginertia="8.01969e-06 7.70194e-06 2.31775e-06"/>
      <joint name="Revolute 47" pos="0 0 0" axis="0 0 1"/>
      <geom pos="-0.11 -0.05 0.163" type="mesh" rgba="0.7 0.7 0.7 1" mesh="motor_shaft_1"/>
      <geom pos="-0.11 -0.05 0.163" quat="1 0 0 0" type="mesh" rgba="0.7 0.7 0.7 1" mesh="Link1_1"/>
      <body name="Link2_1" pos="0.02 0 0.0195">
        <inertial pos="0.047 0 0.005" quat="0 0.707107 0 0.707107" mass="0.168204" diaginertia="0.000169 0.000165 7e-06"/>
        <joint name="Revolute 49" range = "-0 0" pos="0 0 0" axis="0 0 -1"/>
        <geom pos="-0.13 -0.05 0.1435" quat="1 0 0 0" type="mesh" rgba="0.7 0.7 0.7 1" mesh="Link2_1"/>
        <body name="Link3_1" pos="0.094 0 0">
          <inertial pos="0.107601 0.000766691 -0.00489777" quat="-0.0322869 0.706513 -0.0494 0.705235" mass="0.246508" diaginertia="0.00062561 0.000617884 9.1756e-05"/>
          <joint name="Revolute 50" pos="0 0 0" axis="0 0 -1"/>
          <geom pos="-0.224 -0.05 0.1435" quat="1 0 0 0" type="mesh" rgba="0.7 0.7 0.7 1" mesh="Link3_1"/>
          <geom pos="-0.2135 -0.05 0.1435" quat="1 0 0 0" type="mesh" rgba="0.7 0.7 0.7 1" mesh="Shaft_1"/>
          <geom pos="-0.224 -0.05 0.1435" type="mesh" rgba="0.7 0.7 0.7 1" mesh="Impact_Plate_1"/>
        </body>
      </body>
    </body>
  </worldbody>

  <actuator>
    <!-- <position name="forward" cranksite="cranksite" slidersite="impact_site" cranklength=".008"/> -->
    <position joint="Revolute 47" ctrlrange="-1 1" ctrllimited="true" />
  </actuator>
</mujoco>
